[2023-06-08 18:05:40,801] {taskinstance.py:1037} INFO - Dependencies all met for <TaskInstance: dag_combustivel.get_op scheduled__2019-07-01T00:00:00+00:00 [queued]>
[2023-06-08 18:05:40,812] {taskinstance.py:1037} INFO - Dependencies all met for <TaskInstance: dag_combustivel.get_op scheduled__2019-07-01T00:00:00+00:00 [queued]>
[2023-06-08 18:05:40,813] {taskinstance.py:1243} INFO - 
--------------------------------------------------------------------------------
[2023-06-08 18:05:40,813] {taskinstance.py:1244} INFO - Starting attempt 1 of 1
[2023-06-08 18:05:40,814] {taskinstance.py:1245} INFO - 
--------------------------------------------------------------------------------
[2023-06-08 18:05:40,838] {taskinstance.py:1264} INFO - Executing <Task(SimpleHttpOperator): get_op> on 2019-07-01 00:00:00+00:00
[2023-06-08 18:05:40,844] {standard_task_runner.py:52} INFO - Started process 2841 to run task
[2023-06-08 18:05:40,848] {standard_task_runner.py:76} INFO - Running: ['***', 'tasks', 'run', 'dag_combustivel', 'get_op', 'scheduled__2019-07-01T00:00:00+00:00', '--job-id', '55', '--raw', '--subdir', 'DAGS_FOLDER/dag_combustivel.py', '--cfg-path', '/tmp/tmptxbzb8vo', '--error-file', '/tmp/tmp0snk4yyd']
[2023-06-08 18:05:40,850] {standard_task_runner.py:77} INFO - Job 55: Subtask get_op
[2023-06-08 18:05:40,916] {logging_mixin.py:109} INFO - Running <TaskInstance: dag_combustivel.get_op scheduled__2019-07-01T00:00:00+00:00 [running]> on host b35b0064e2f2
[2023-06-08 18:05:40,983] {taskinstance.py:1431} INFO - Exporting the following env vars:
AIRFLOW_CTX_DAG_OWNER=***
AIRFLOW_CTX_DAG_ID=dag_combustivel
AIRFLOW_CTX_TASK_ID=get_op
AIRFLOW_CTX_EXECUTION_DATE=2019-07-01T00:00:00+00:00
AIRFLOW_CTX_DAG_RUN_ID=scheduled__2019-07-01T00:00:00+00:00
[2023-06-08 18:05:40,984] {http.py:104} INFO - Calling HTTP method
[2023-06-08 18:05:40,995] {base.py:79} INFO - Using connection to: id: stack-data-pipeline. Host: https://gcp-datapipeline-zg5jnixfka-uc.a.run.app, Port: None, Schema: , Login: , Password: None, extra: {}
[2023-06-08 18:05:40,997] {http.py:129} INFO - Sending 'POST' to url: https://gcp-datapipeline-zg5jnixfka-uc.a.run.app/download_combustivel
[2023-06-08 18:05:41,138] {http.py:142} ERROR - HTTP error: Not Found
[2023-06-08 18:05:41,139] {http.py:143} ERROR - 
<html><head>
<meta http-equiv="content-type" content="text/html;charset=utf-8">
<title>404 Page not found</title>
</head>
<body text=#000000 bgcolor=#ffffff>
<h1>Error: Page not found</h1>
<h2>The requested URL was not found on this server.</h2>
<h2></h2>
</body></html>

[2023-06-08 18:05:41,151] {taskinstance.py:1718} ERROR - Task failed with exception
Traceback (most recent call last):
  File "/home/airflow/.local/lib/python3.7/site-packages/airflow/providers/http/hooks/http.py", line 140, in check_response
    response.raise_for_status()
  File "/home/airflow/.local/lib/python3.7/site-packages/requests/models.py", line 960, in raise_for_status
    raise HTTPError(http_error_msg, response=self)
requests.exceptions.HTTPError: 404 Client Error: Not Found for url: https://gcp-datapipeline-zg5jnixfka-uc.a.run.app/download_combustivel

During handling of the above exception, another exception occurred:

Traceback (most recent call last):
  File "/home/airflow/.local/lib/python3.7/site-packages/airflow/models/taskinstance.py", line 1334, in _run_raw_task
    self._execute_task_with_callbacks(context)
  File "/home/airflow/.local/lib/python3.7/site-packages/airflow/models/taskinstance.py", line 1460, in _execute_task_with_callbacks
    result = self._execute_task(context, self.task)
  File "/home/airflow/.local/lib/python3.7/site-packages/airflow/models/taskinstance.py", line 1516, in _execute_task
    result = execute_callable(context=context)
  File "/home/airflow/.local/lib/python3.7/site-packages/airflow/providers/http/operators/http.py", line 106, in execute
    response = http.run(self.endpoint, self.data, self.headers, self.extra_options)
  File "/home/airflow/.local/lib/python3.7/site-packages/airflow/providers/http/hooks/http.py", line 130, in run
    return self.run_and_check(session, prepped_request, extra_options)
  File "/home/airflow/.local/lib/python3.7/site-packages/airflow/providers/http/hooks/http.py", line 183, in run_and_check
    self.check_response(response)
  File "/home/airflow/.local/lib/python3.7/site-packages/airflow/providers/http/hooks/http.py", line 144, in check_response
    raise AirflowException(str(response.status_code) + ":" + response.reason)
airflow.exceptions.AirflowException: 404:Not Found
[2023-06-08 18:05:41,158] {taskinstance.py:1282} INFO - Marking task as FAILED. dag_id=dag_combustivel, task_id=get_op, execution_date=20190701T000000, start_date=20230608T180540, end_date=20230608T180541
[2023-06-08 18:05:41,172] {standard_task_runner.py:92} ERROR - Failed to execute job 55 for task get_op
Traceback (most recent call last):
  File "/home/airflow/.local/lib/python3.7/site-packages/airflow/providers/http/hooks/http.py", line 140, in check_response
    response.raise_for_status()
  File "/home/airflow/.local/lib/python3.7/site-packages/requests/models.py", line 960, in raise_for_status
    raise HTTPError(http_error_msg, response=self)
requests.exceptions.HTTPError: 404 Client Error: Not Found for url: https://gcp-datapipeline-zg5jnixfka-uc.a.run.app/download_combustivel

During handling of the above exception, another exception occurred:

Traceback (most recent call last):
  File "/home/airflow/.local/lib/python3.7/site-packages/airflow/task/task_runner/standard_task_runner.py", line 85, in _start_by_fork
    args.func(args, dag=self.dag)
  File "/home/airflow/.local/lib/python3.7/site-packages/airflow/cli/cli_parser.py", line 48, in command
    return func(*args, **kwargs)
  File "/home/airflow/.local/lib/python3.7/site-packages/airflow/utils/cli.py", line 92, in wrapper
    return f(*args, **kwargs)
  File "/home/airflow/.local/lib/python3.7/site-packages/airflow/cli/commands/task_command.py", line 298, in task_run
    _run_task_by_selected_method(args, dag, ti)
  File "/home/airflow/.local/lib/python3.7/site-packages/airflow/cli/commands/task_command.py", line 107, in _run_task_by_selected_method
    _run_raw_task(args, ti)
  File "/home/airflow/.local/lib/python3.7/site-packages/airflow/cli/commands/task_command.py", line 184, in _run_raw_task
    error_file=args.error_file,
  File "/home/airflow/.local/lib/python3.7/site-packages/airflow/utils/session.py", line 70, in wrapper
    return func(*args, session=session, **kwargs)
  File "/home/airflow/.local/lib/python3.7/site-packages/airflow/models/taskinstance.py", line 1334, in _run_raw_task
    self._execute_task_with_callbacks(context)
  File "/home/airflow/.local/lib/python3.7/site-packages/airflow/models/taskinstance.py", line 1460, in _execute_task_with_callbacks
    result = self._execute_task(context, self.task)
  File "/home/airflow/.local/lib/python3.7/site-packages/airflow/models/taskinstance.py", line 1516, in _execute_task
    result = execute_callable(context=context)
  File "/home/airflow/.local/lib/python3.7/site-packages/airflow/providers/http/operators/http.py", line 106, in execute
    response = http.run(self.endpoint, self.data, self.headers, self.extra_options)
  File "/home/airflow/.local/lib/python3.7/site-packages/airflow/providers/http/hooks/http.py", line 130, in run
    return self.run_and_check(session, prepped_request, extra_options)
  File "/home/airflow/.local/lib/python3.7/site-packages/airflow/providers/http/hooks/http.py", line 183, in run_and_check
    self.check_response(response)
  File "/home/airflow/.local/lib/python3.7/site-packages/airflow/providers/http/hooks/http.py", line 144, in check_response
    raise AirflowException(str(response.status_code) + ":" + response.reason)
airflow.exceptions.AirflowException: 404:Not Found
[2023-06-08 18:05:41,181] {local_task_job.py:154} INFO - Task exited with return code 1
[2023-06-08 18:05:41,221] {local_task_job.py:264} INFO - 0 downstream tasks scheduled from follow-on schedule check
